# 天翼云盘签到记录

[![签到状态](https://github.com/chanho0/189pan/actions/workflows/main.yml/badge.svg)](https://github.com/chanho0/189pan/actions/workflows/main.yml) [![项目主页](https://img.shields.io/badge/GitHub-项目主页-blue?logo=github)](https://github.com/chanho0/189pan)

**最后更新:** 2025-10-18 10:40:49 CST

## 快速导航

- 🔄 [查看Action运行记录](https://github.com/chanho0/189pan/actions)
- 📋 [查看最新运行](https://github.com/chanho0/189pan/actions/runs/18609560044)
- 🏠 [返回项目主页](https://github.com/chanho0/189pan)
- ⚙️ [手动触发签到](https://github.com/chanho0/189pan/actions/workflows/main.yml)

## 签到详情

# 天翼云盘自动签到抽奖程序

## 执行概览
- **启动时间**: 2025-10-18 10:40:49
- **账户数量**: 2 个

## 账户1
登录过程出错: HTTPSConnectionPool(host='open.e.189.cn', port=443): Max retries exceeded with url: /api/logbox/oauth2/autoLogin.do?appId=cloud&version=v1.1&clientType=20010&format=redirect&paras=321B0CA933442723C2CB6D361499165914BB6BD89BDC08BD14EEBC612DF5F21F84AAAA1E7E8FAAF78D9B1E92345AF782504792C6DE033A3D40AC28DBC78FF9F7106C9B16310504E85A072E53487E94867D9587DF4D7D9EB5D61B72E33AD2950BAC821CC453F77DC450BEE10C1E7AAE55113D01389D9F6B885928C1E898C6513D76F423199E63525122144D59BD76B9F7DBA04D111FEFC42C7B57CBD028FE30D55F9976310178E264BF3C07A4495D98FC307C81F5A36FA88185169A02D745ACC403EB2964AFD1CCE1D19A700552EE85E9FA9F442873BBE3F856177DF72310D4D7F022ECCC57F137FD6A4EF69F329CB0BAAEBF3CBF6D370D7366C3DE2AEDECBE19D598D9EE6CB0C569922BF355DD79E9E8D385E97CBB0066CDFD2A376C5C573AB6C124DB9B968E946E96A428D9538246DD9FCA3F590D750AFE78990953362663F868095E4AACC91BD12CF87255DB42326EDCCB2E4AB463B2B4100A18D0DF7AE3A0B1FBB75F80E8B877F4A6948274D4F8CE9C598DE34060D50A07A900BD5DA0EB6C8B546A214EA8C8FDB9C32EE6D5D59FFFBC4F885B146288BC43BE3D313EC3D891492E68D95707697A797CF5A7DE72E6DA03991BA1E68BC68FF69DF78802DB7E31DF4398BE2249D82CC3022BA92C62AA73ECB82522BE76AFE2CC923BF4D29B6E32105A6209536D30D1FCC7B6392015C69141EB3BFF66244D998D9D1C9F09DE7499538B5E1A6987B6B1A5696D7CD6F0FF0EEFE4EBFF66B485AE&sign=2823CD679CD339AA3E5B31DC8B14593A91ACC130 (Caused by NewConnectionError('<urllib3.connection.HTTPSConnection object at 0x7f8ae1ae4a50>: Failed to establish a new connection: [Errno 101] Network is unreachable'))
### 执行结果
- **登录状态**: 登录失败
- **签到结果**: 

## 账户2
登录过程出错: HTTPSConnectionPool(host='open.e.189.cn', port=443): Max retries exceeded with url: /api/logbox/oauth2/autoLogin.do?appId=cloud&version=v1.1&clientType=20010&format=redirect&paras=286E231EEED3E34FFB4EA133E1351674512DD7A8FFE4421CD1733E740A265A8A1A1567AFF641A291E2145AB346FB22542ED850746168092F6DAC89AA916914AF8A86F67A4D5FB2053900FCA37D503E2C485471DB3664DA80FAAE54603951FA1E1183F7675524637A28B5D87093FC547A1807C1EC279FE696DCF39D0FDCEB46C6A5A0F0F198142CB1DE42AEA4CF43AEE6F098DBC12E171F31EDE8C8915CAD6863106C0A6F0604BFE9F7DAD3E9E4778A4FD727959AEAFAB559C8A10301950F088E66F297518E718D6FF3632B147026CAEF5E0366B706BE027658434B93FCD04855734FB6CFE7BEA5B9BF237250B9C5006D8C1BFC72A1E4F7616450D097E60B45AEB83AA83FDFA4B26CF083C5D568453E8A59372776AF5A7C43910B82DA871E54FBE164EE6F5EC92D8FC305DDA77D72B4F6720C80199ACF6083B6C1AE8965CB7F1E789B4FC1B8AE681284F16A568A021DC29198D87D678F6AB69E12A77C4EAF27F5F7A26E570B8FCC2A684802B79C532245216945FC2135D5D7073CBD20BF3D0F6C7E7CAF8CE9BC8B30D4D3E5ECC9D9813F8C583E00DBFD14A658B346B056E75342124D3AD5DDF685E7DB9B6326FE1DA44ECA0C65278E2776D4FBA5130D2CA374E2A43F63B017BAB84E1701A0DA699CD21051E0EFC26D7261EAE132A1E064612DE165496FEFB54AF9B3EF38B01F1842D63BB4839190E75917137BE500E76DBB4A63C32DAA01922C9BD13DBDE89F20252D34CB0968C94712EC0B&sign=BAF98D2E83CF6526F58BB669DEEC8EBE47D4EEEC (Caused by NewConnectionError('<urllib3.connection.HTTPSConnection object at 0x7f8ae1ae8210>: Failed to establish a new connection: [Errno 101] Network is unreachable'))
### 执行结果
- **登录状态**: 登录失败
- **签到结果**: 

---
## 执行统计
- **结束时间**: 2025-10-18 10:49:52
- **运行时长**: 543.11 秒

✅ **所有账户处理完成！**
