# 天翼云盘签到记录

[![签到状态](https://github.com/chanho0/189pan/actions/workflows/main.yml/badge.svg)](https://github.com/chanho0/189pan/actions/workflows/main.yml) [![项目主页](https://img.shields.io/badge/GitHub-项目主页-blue?logo=github)](https://github.com/chanho0/189pan)

**最后更新:** 2025-10-18 21:39:06 CST

## 快速导航

- 🔄 [查看Action运行记录](https://github.com/chanho0/189pan/actions)
- 📋 [查看最新运行](https://github.com/chanho0/189pan/actions/runs/18616380644)
- 🏠 [返回项目主页](https://github.com/chanho0/189pan)
- ⚙️ [手动触发签到](https://github.com/chanho0/189pan/actions/workflows/main.yml)

## 签到详情

# 天翼云盘自动签到抽奖程序

## 执行概览
- **启动时间**: 2025-10-18 21:39:06
- **账户数量**: 2 个

## 账户1
登录过程出错: HTTPSConnectionPool(host='open.e.189.cn', port=443): Max retries exceeded with url: /api/logbox/oauth2/autoLogin.do?appId=cloud&version=v1.1&clientType=20010&format=redirect&paras=1D55D2CA842F3E2F637E8FEC9C70B3175E91DA68A21B3BD4EAB48FE548E6F334721EFA909C8DF900BD1EAD9194A3C93000A092D9528DA1CF9ADBFF2BDD27D280B22999658D50D3FC06BFC45200641CB856E3855BBBA05C909921A76CEE66C8A27470F118533BBBFCEA3813F0833206885B401B97A97803A14F183F104D84F17005D389CDD310D45DB28F9184D61D92991056A6D5627ED542598464A0D5A3B13D0CBEF5C5B85C749AA5D4FA823C9AA9CDA944018C61EE1DF1F2887F93DD85CADA8B096B9EFA0F5BCABEDAB9F30D6B230679088A0B05DA9FA97A47F3DC16C4D8F0E2A7A5EBE5153B8D158E8E33E93604B8D65D8425695863A39D4DB646094F52BF6AA797BFD4D03C2268C7C1B67DDDD23ADA39A87DA3C091BFBAD9C0F778CADDF1D1E1322767C61106023466CB41BF35AA8FBF3726255B67AC5F367F76BED320269628C0A5AA9ACEFBA4A3A7696D5FF686467495F47EC30957EECED68EA9AAB48E962A20728C120F352B1659C2F8F931B59BDA18E349F45E8F4A8BA44F8600B971A46CA7014732CAB2AAF0585FDA873F145C11D61130C3B54D1DE27FD25097DFD418D9A2F12D8A37D9DE753FD2B8D869C78B90D624FA8883A1BAB4D3137102576E002A00E0949F9D7E7F79E67352B687040F058112A556282C62931F61228F9C477944AD472551B464DE48F170DBCF43669ECC672B5B59BD4540B6BEF7E4A674D665505BE2F1C385E62122BF0B345F8B6951CA742CE310911B&sign=8D4F1E6839D897FBB4BE0B29B7EE514AF5B69C07 (Caused by NewConnectionError('<urllib3.connection.HTTPSConnection object at 0x7fe0ec84ca10>: Failed to establish a new connection: [Errno 101] Network is unreachable'))
### 执行结果
- **登录状态**: 登录失败
- **签到结果**: 

## 账户2
登录过程出错: HTTPSConnectionPool(host='open.e.189.cn', port=443): Max retries exceeded with url: /api/logbox/oauth2/autoLogin.do?appId=cloud&version=v1.1&clientType=20010&format=redirect&paras=08A0B8538FD53B8CEC1AA463ED478EEE910662DFD4FF6B179B888D3D6B3A869B05B48204C93821DE0C16039F868E8F5A6E74731AA88569C7178AE2CACF2FFC76C389ECADA4372A5F5E0504658AB807F5582309BAA308C45B00224D85FD32887CDD15C9538FD2E39AAF9D92EA80A6D4F6BBB458899A76639454EB6E8560B0C0D1A3749C796753904CB4693E9C7719484A4C26AFBCE658DD635BEEE2A348A2561487AF66C818BEE1A5F6FDA5975E83DF626706C9D1A9B46D45B84F7D27E0BF35D9AE8C37FADF65E720B646A5208D33F0F1E1931582C66AC11C8F4D9BFDCAAF9CBCE18CB5ABE5E57CD875E797E0501DFA2954EF595CCED50350F8B391FF2CCB249C64F3957AB70D8B41A8BDDF087F4DD40C70934A09CE5F82273D971936E7591F41BA8F9143BF7E4CFC8E8136F61A5D5EE49C195A433AF98D1EAF0192CF717B13771D09A2C8D6AA57D873FB6DB82D08323C62ECCBDEE220406740C6C0E68357148FD322935DB2A305F361D16E76B41B8D43FDF5C5FB2A4B230E8C5B4C7D248463D9F3791BFECE88F0175B1C1AEE1C3EF98D48478946A286CA8553467CF8035819F4DEB28197DEAF21097FA716B579EBEA54B32A5A9D4E9F1F968B34D0B1E3E324DB1A82ECD6788E7FAEFEA02504DAF3646FAC2AA7FFC0E62DE8DF4A3F48BDC50ED1D58EE54BA68B76B1CDBFDC3927ED2A271766929921A6478E15506CD4BC9A2930A3E2E7ACF1E123F50F9CC599581B6ECD16A72BA0565B9A56&sign=902DC8C84EE5BD0FD423F99A9E788F667E585B35 (Caused by NewConnectionError('<urllib3.connection.HTTPSConnection object at 0x7fe0ec850210>: Failed to establish a new connection: [Errno 101] Network is unreachable'))
### 执行结果
- **登录状态**: 登录失败
- **签到结果**: 

---
## 执行统计
- **结束时间**: 2025-10-18 21:48:11
- **运行时长**: 544.17 秒

✅ **所有账户处理完成！**
