# 天翼云盘签到记录

[![签到状态](https://github.com/chanho0/189pan/actions/workflows/main.yml/badge.svg)](https://github.com/chanho0/189pan/actions/workflows/main.yml) [![项目主页](https://img.shields.io/badge/GitHub-项目主页-blue?logo=github)](https://github.com/chanho0/189pan)

**最后更新:** 2025-10-14 10:46:59 CST

## 快速导航

- 🔄 [查看Action运行记录](https://github.com/chanho0/189pan/actions)
- 📋 [查看最新运行](https://github.com/chanho0/189pan/actions/runs/18483890439)
- 🏠 [返回项目主页](https://github.com/chanho0/189pan)
- ⚙️ [手动触发签到](https://github.com/chanho0/189pan/actions/workflows/main.yml)

## 签到详情

# 天翼云盘自动签到抽奖程序

## 执行概览
- **启动时间**: 2025-10-14 10:46:59
- **账户数量**: 2 个

## 账户1
登录过程出错: HTTPSConnectionPool(host='open.e.189.cn', port=443): Max retries exceeded with url: /api/logbox/oauth2/autoLogin.do?appId=cloud&version=v1.1&clientType=20010&format=redirect&paras=410C56577D0084A8CDA962AADAB845BBB034FD5F7763868C50FC0F0237C88F9DEB490975221E69027544F32F777BBDD57644E11BFB25BE985C3EBE8EBB7F0E41E9D90D64F367E72B7859A6E83326488D023F3609850236F447BDCC73B19DE3C40724647234033BB1EA390940840911AEFF0380E8811720253645F8DA4381F5D0E6732BFB854A29917C27BDFC57AC25B0F19B932805D913247D62CEF7A5E62B49108AEA34E3C579576E69911978DC7E5E0E7B587B83EEDFBFB8AE8242E8FA77CDCD8772CBD834CBFAD55F321892E3BF3174BADD2BED2AC41680A562F8D55BE2BCB484534BA1ACD97A60786E0884EE619C09D098E7B38B9B2B9DBFD14139BD69408C9A4DAAB404969C958F8CDEBE2B54810C932C81DEC90D81603D138955E1D7C0CFB890BFAA958AF3C3250C74459D109313F69BCABF99AFEE8AB814B12B2A079D0CA10C96E4F7DDB5A7A6B02AED1A650C575A47C8660EFCB5E7D6251EAEC66C234145841370B0F2EAFF9C9636D472D7E2204EBC44DE52F70B8920FF0385AC442844371E84198DCB6D17B3DB64779C510B476CC08C1BCD0058E66B98D43FB28685AF0047E4E3BDD716E2D532E86F21AAF0FCEBDF3B2F1EC448D4496C12DF37D1974C15F9AA3EC92129BBAF2275C50173C5452C59F206AAC889F6EB9C294BEBE0DBF52750C9DAD9A3896B2D10A8E6B8DDF3C0B7C7C026FD3638EBEABC8E8520996AB007F8C44D192E56D2806AA14F4F642BE47AA36192EBC52C&sign=D40094DAC019AA1C7F5388B1ABE443038E07A621 (Caused by NewConnectionError('<urllib3.connection.HTTPSConnection object at 0x7f86aa4e0b90>: Failed to establish a new connection: [Errno 101] Network is unreachable'))
### 执行结果
- **登录状态**: 登录失败
- **签到结果**: 

## 账户2
登录过程出错: HTTPSConnectionPool(host='open.e.189.cn', port=443): Max retries exceeded with url: /api/logbox/oauth2/autoLogin.do?appId=cloud&version=v1.1&clientType=20010&format=redirect&paras=88EA41E9ACD90531C46D0162C91226CA909B79E9FA2D162114A1CDAB116970695389D88F5320DB08040540CEECA94CA9FA4B8D94C6F4349372245C20F5C6DF8D3BDD2CE43B96B6EC35904DC9135FCD9FB6E85B82E6BA9940704BF5F1B947E87B50D65FA43AE86DF34045E28237882B4953EAB5BD05902EBE189E0373018E1C781086C9226A9CDFF7274C2B5E8F3DA40BAFB0BF14106DF2213F50C1B1E8BDFD88F44095922871639861FF97CE1AEF1046431FD1EADBDFA77B1FDAA338420022552C3F53179664F0AF0DF4BFC478B98D9CB07885BFDAC574CA9116868CF4F0427FE2271D5D4ADFE6947863929EB0BB5BE90E879C7AC6BFA21E0D31B7CB54557DFF29D33FFA54CBCD0EE9E9D390B8C6AD52D800CF24088F98302D23476B5DFACBF988635A0E3A31533112E79E2C625301BA117ED5D440642E12364956D06B920C4666063BB84F1E38A105A04902D8C4BC221FE02DD0F78B643790B8F24D7A9536FCE648FB8A3AB3F7A4893BCE2F5AD67BD2785C00B7A88F9BD612DD139E310016A1247DF0EBA0E02203A013845EB77CB5DD1BB06924E7CA20BA51806418FF95DD7CD4D1DA560B905748A88150C956CE68A25AEF2AECA77BAC484DA448BE670F29B9DE6C1BDBE59199D343F124A6045CEF43D485E58F699880A77ED8D7EE2F119CDD261188A696AD7F30F96C1927FACF98C46B6AA637DE63268FE3D2E81BED3A22FDB68251A845233C1BF3FDC7CB027E430D8D2F8EA5E0146E22&sign=5003D7EDE726FFBA5C3C7D8D289E60951062E53E (Caused by NewConnectionError('<urllib3.connection.HTTPSConnection object at 0x7f86aa4ec390>: Failed to establish a new connection: [Errno 101] Network is unreachable'))
### 执行结果
- **登录状态**: 登录失败
- **签到结果**: 

---
## 执行统计
- **结束时间**: 2025-10-14 10:56:02
- **运行时长**: 542.61 秒

✅ **所有账户处理完成！**
