# 天翼云盘签到记录

[![签到状态](https://github.com/chanho0/189pan/actions/workflows/main.yml/badge.svg)](https://github.com/chanho0/189pan/actions/workflows/main.yml) [![项目主页](https://img.shields.io/badge/GitHub-项目主页-blue?logo=github)](https://github.com/chanho0/189pan)

**最后更新:** 2025-08-10 21:46:54 CST

## 快速导航

- 🔄 [查看Action运行记录](https://github.com/chanho0/189pan/actions)
- 📋 [查看最新运行](https://github.com/chanho0/189pan/actions/runs/16862213205)
- 🏠 [返回项目主页](https://github.com/chanho0/189pan)
- ⚙️ [手动触发签到](https://github.com/chanho0/189pan/actions/workflows/main.yml)

## 签到详情

# 天翼云盘自动签到抽奖程序

## 执行概览
- **启动时间**: 2025-08-10 21:46:54
- **账户数量**: 2 个

## 账户1
登录过程出错: HTTPSConnectionPool(host='open.e.189.cn', port=443): Max retries exceeded with url: /api/logbox/oauth2/autoLogin.do?appId=cloud&version=v1.1&clientType=20010&format=redirect&paras=E0C82D80DDDBF587D6D2312BB8C5EA594C126ADFB22DF2490A6DC43CD87D39CDEF3A6E2F91DC4F28668D93B0B1529D83ECA6DEA64DA1FF08317FD088C7EA5E7C17703594216B1BE73DEFB892B4BBD80EFB80DDDAB5BC94040EBC0BBB36D0874DAFA6D51AB54FF8B77FB955E8F48AD39050F62AE4EEDB9FE5B895C6F4B9406AA7CEABEDDC7CA02914E61DA6A1EE58882ECC1020E1C27CB1D6DB0D153E22C55D1315F3AA5017FBAE1518FB0CDA7A087C24B9BD0011BB26DE0851DB3D125A60030F0CBC437BDF63B8B7AAA06B9EDF003C5917B65D970B0A03FC714D2757C2044D5432FA90686F2AF21A4865C6BA39035096A5DD6F9E5CEE0C58F52BE69B1403DC181477A3D38FA4A30371388666021938184A7441FF152C0F23953F9AEC562CEDB8A57197AF5B7400E2359BABC2BB38F6B6D8485CDF5E21B0F884057271CF3927138480824517CBD1FB51F48CA9CB6D400EEE777619E1B2D4454270509DB166903EBE66EC98C74C5F6F2E8A497DD96D0F535C86CE85CB192065BD4A1F0DDE8ACE81CC648C298436EA65AC58A980D874EB8ABE9D6FB3D81B2609EB41E6E26C7870C6E83CE9C21FCBD63ED375B9272F3171C17202DCF869E80F05B8B4E69DAB1F599BA003F6D2E73AF6781322282005D53BEBB220AFF8240C2EE648823D08DA7F2897FFA04FA3B91FA9ABA898055E75C03CFFE399C0C66FE537A3CA4AE27E24915D2E2B3D7FB5442869333C70A6072D5BB598EF87B8927757BE0F&sign=9912A1AFA1EF0B9C6A12D3802E94F6FD26893F65 (Caused by NewConnectionError('<urllib3.connection.HTTPSConnection object at 0x7f694a8e47d0>: Failed to establish a new connection: [Errno 101] Network is unreachable'))
### 执行结果
- **登录状态**: 登录失败
- **签到结果**: 

## 账户2
登录过程出错: HTTPSConnectionPool(host='open.e.189.cn', port=443): Max retries exceeded with url: /api/logbox/oauth2/autoLogin.do?appId=cloud&version=v1.1&clientType=20010&format=redirect&paras=2D4DAF27F87E6FA76C9D41427276E2CEA553F0CB995DC053227A938C4FC332B4C41898DF33BF317DCB5EC24510191753FA5F27C96A1257346FD37CEBD88310B246DAA6D2F283A7D065991A20AC158FD82809344A31180F792D6C025EBFC282A9490FC2894E2DA9EF1DD846E1C04C5D08EB716AE077168DBF71D4A5FA5ECAB1D2F6527B790D3773908FA18F33E389A958A2BA04D90F8EBCF3E7CE5F7B322594E0B6A53FBAE0C192E88131DE049207016842F8B23BAFA6AE63F24D5E9AA6679BED477B7DB999B1C41C6B082DF7E61E64FCEE23D18441439FA721D7EBF2B6A5873196AEB97959CB65BC2C1B2C7678C7D9243163863E310FE680AE2E7848FF22AFD5B41DC2AD9A524CDC06EB3191A2E958C5BCE34CC540EFF40DE65AA930A962E183BA7897F157134D468F88B621EA41044C038B24E94E006DC8688A9708C4C6C4FF37CF17593420EB235B7AB74E7FF52499BCF602D49A62F82579CA9E7FB26942BC4FB2DDC84C44313CB5D0E5144F7D67DDCCB531FE41E2BF3D8DC2079DB44CA735D86ECEB3483A7CB852C2D436E0570A7A4B7DBD55BFB4E54D9127966B4407FB9A35927F2EB0E1610521AF0606CC9D99559F8B5C148DABDDCCB88961B2F10A417FF384EB00490B47AC8CFE343BDCED4658F2D4F2213FDFBDD958B1663A7D14840D33DE4055EBAB356F86D312E24011ECBDFE1FDF57D31ACCF55CB3C2BD4F249035575E8A06F5836A76A87D492E5F0545202399DD170B6D0E86&sign=5CE02F9315FB65CB3C7AB12BFBA4602EE60A2AB3 (Caused by NewConnectionError('<urllib3.connection.HTTPSConnection object at 0x7f694a8e7f90>: Failed to establish a new connection: [Errno 101] Network is unreachable'))
### 执行结果
- **登录状态**: 登录失败
- **签到结果**: 

---
## 执行统计
- **结束时间**: 2025-08-10 21:55:58
- **运行时长**: 544.48 秒

✅ **所有账户处理完成！**
