# 天翼云盘签到记录

[![签到状态](https://github.com/chanho0/189pan/actions/workflows/main.yml/badge.svg)](https://github.com/chanho0/189pan/actions/workflows/main.yml) [![项目主页](https://img.shields.io/badge/GitHub-项目主页-blue?logo=github)](https://github.com/chanho0/189pan)

**最后更新:** 2025-08-10 11:22:56 CST

## 快速导航

- 🔄 [查看Action运行记录](https://github.com/chanho0/189pan/actions)
- 📋 [查看最新运行](https://github.com/chanho0/189pan/actions/runs/16856721957)
- 🏠 [返回项目主页](https://github.com/chanho0/189pan)
- ⚙️ [手动触发签到](https://github.com/chanho0/189pan/actions/workflows/main.yml)

## 签到详情

# 天翼云盘自动签到抽奖程序

## 执行概览
- **启动时间**: 2025-08-10 11:22:56
- **账户数量**: 2 个

## 账户1
登录过程出错: HTTPSConnectionPool(host='open.e.189.cn', port=443): Max retries exceeded with url: /api/logbox/oauth2/autoLogin.do?appId=cloud&version=v1.1&clientType=20010&format=redirect&paras=D39B961C85C3A5E11243329F04F8C326EC50C98E90D6C249CA5D945066BD3DC5BE5F1B7933499F236CC30C2966D787B441318B45BD690C988BA8A512A2DB33206198B273BE02818E10091AB0DCABE19DAF0E46620AC549A967BD7922EFEFEBC82A3ACB30D8E12C4D4955728655B3BB9E87BEBB053B7729D81E95F2395F72E7745DAD36CC430C5478999BC2AC8FED783CB01ADE0CD51B39DFF2D743490B91698E0897B839331BE1ADE731BA60C11CCEBED73B0B6F3754A7584232958E024185FF49FCFAE1398103F358BDA3AFC856BE33750E640E0A259F21991F5965479AF01C4D67384A75C2BF64F5C29FC845E2F690C6F003C47BA40EAF24718C1031B942062DEACB6E28E886F0677BE9D9D56FF2B23F872A51C4EC74110D1F753A39F598E7F69747FE9DC965D86000F96425BABB3898B68BF4E229CBF99215782CB7F390590FD9FCD9C5510940966F151930C54D57499A92D559973945E3D3362E2F77BD32BA9764E6B80CE41E4BD3D8F100C138787ECC16C10179B0EFAC45D47180271FD42F2DFEA6EB9E465E72DF733654B8366799A0D80384CE09381C18384F9923FC6854BFE5CDAB3E4FA3B758941CB8C4D2B20C88E355819E2BD2C868F8A2176AD4E82077CA4511AAEF9AE88F42C653B89B2058D9C30C03A608F25491FB5FFFEF8618F98F6151F10DE89AFDA89589DFFA1BBFD370BFEC472DA186F2A275AE73C105E99E6D939062575DA824B3B6EE58B1C091067380BCCA585194&sign=FBE79C0BAC90F659255996153F6BF3CF6FF82572 (Caused by NewConnectionError('<urllib3.connection.HTTPSConnection object at 0x7f9750be49d0>: Failed to establish a new connection: [Errno 101] Network is unreachable'))
### 执行结果
- **登录状态**: 登录失败
- **签到结果**: 

## 账户2
登录过程出错: HTTPSConnectionPool(host='open.e.189.cn', port=443): Max retries exceeded with url: /api/logbox/oauth2/autoLogin.do?appId=cloud&version=v1.1&clientType=20010&format=redirect&paras=95CDE881DB4CB3EF0677FF52BC713FD94E199E941DE1932BFB5857037031FBA78574BCF4F4BF55BCBF7647795EB19D5EA2FC3B2A536077011700A0A9B77416C85509168483B575E623DB25BFE512F1C08CC4543EE6493A9927699F8B7F3C27A4B9822E9515D229F586816A96E057AF5293FF779E4ED4C645D2B4FB09D4CA8513FF4B5AF181A996953CCF16DFEA949FD272DCF305C2DD6B4CAA12D06C52C38F5032C158905C3C9572B95566B6EB0FDA9CE2990C38558D5F7592295AD30D14A05D25B208D7750AEED8AB202C673142BDBF4738ADCCA1B15521FDA82A0B4C15814E70591745395E4B7A318215183B7A74906A1FBA9C035A4F5A0321087DDE097618516FAEFFEF5C597F26B39F671FC323AAF3164582D7E9E4DEA73A14E1FA56A6EC7FCD4ADDFC16B8C9848B72FE7C0B1D98D471F902E5949220EE8622350AB9153CFF0A0462963581C2BE77FEABC0AEE8BD5921007871DBC3252653F6340244AAC42934665CEF9DDAB0EC40F0234C7F39DAC53416A5002AA7B43750A181A40EF9FD4B6A890A3AE8B11B5F776F8E4C6F486108114D3FA500C6F48FDB4EBE42836C98980B949D84A415EE1B1F31E28C048AD4DF7D1BD5E195839F4D585B19138DC270CD5FD93E4CDE4D96400B5558694C6662CD129E980756B8B34517D8AD5134C6304648154F50C2920BBBAA95FE778F463AB8D27690ED32E66B54A1EA9EF5861D961D2E90BFEE3433BFFD5F855885C6C2385B99C8A533949EAC&sign=BDC0E7909CB66D5E6D9E56F67D31444DD532A65B (Caused by NewConnectionError('<urllib3.connection.HTTPSConnection object at 0x7f9750bec1d0>: Failed to establish a new connection: [Errno 101] Network is unreachable'))
### 执行结果
- **登录状态**: 登录失败
- **签到结果**: 

---
## 执行统计
- **结束时间**: 2025-08-10 11:31:58
- **运行时长**: 541.76 秒

✅ **所有账户处理完成！**
