# 天翼云盘签到记录

[![签到状态](https://github.com/chanho0/189pan/actions/workflows/main.yml/badge.svg)](https://github.com/chanho0/189pan/actions/workflows/main.yml) [![项目主页](https://img.shields.io/badge/GitHub-项目主页-blue?logo=github)](https://github.com/chanho0/189pan)

**最后更新:** 2025-10-21 21:50:15 CST

## 快速导航

- 🔄 [查看Action运行记录](https://github.com/chanho0/189pan/actions)
- 📋 [查看最新运行](https://github.com/chanho0/189pan/actions/runs/18686090016)
- 🏠 [返回项目主页](https://github.com/chanho0/189pan)
- ⚙️ [手动触发签到](https://github.com/chanho0/189pan/actions/workflows/main.yml)

## 签到详情

# 天翼云盘自动签到抽奖程序

## 执行概览
- **启动时间**: 2025-10-21 21:50:15
- **账户数量**: 2 个

## 账户1
登录过程出错: HTTPSConnectionPool(host='open.e.189.cn', port=443): Max retries exceeded with url: /api/logbox/oauth2/autoLogin.do?appId=cloud&version=v1.1&clientType=20010&format=redirect&paras=6CC1209FD21E281DBD5ADEE70F8D0ABCBDCB1E5F2451D80D500DDD6B98FE2445161292638E40567927C285658F08E0AE4B03642AB6EBD28DB8C7AC3F99292DACD1030D763CE0784AFD3EEB3FFC3A60C24991BECFAE195C0038D3D331B15FF1231EE81F23182E8084DF15A94748A6E0E8B85DFDE9C5620A78EFCC9C4FA7F1AD283D6359BA7EE15894E2BD676A993C76EF73560548B306B1A8EDE1C1D578897E9F9F25A9C712186DF919A12E63521BEC5562339A08854776468C77F35C5EB1FC38A795E04A2E721126654ABEAE5CD6C3720AE725B6661A8EA58B7229D463F59A8C0ED2725CA2564516EC3FCF66D4DF92B112875F14A4F3BB88FD8E6710B7961804706BF1EE4616ED76178C212B11D46F2D6292E85170FB7533514DE8F0E63FCFFFDAA3E12A8CEE46140429818277F80AEF28F59AED59F7F54A9B5F1A3E740E5A105E083221A6F7702612BDDC607BAFD59C3142F77866254F5AEA27D856F1B5BEAA27DAFDAC016E7934BB4B61D46788B3883BF56C1C27789D1BDDEA0FAA87F906E3DFF758D3133DC4D29DAA9F40E51862D9243C87976C4F6A4F189FAD35EB3F7AE5632628EA23D06CF190127474250F2D233C762CF4F8A401B7F669766A55D2EA515FF57B4B79A99667CEE8AA09D632FBA777948916608480C72EBB50560749629D99981369DB61332DEC5066EE0B40B01C06EFD5CC0AB0FA964A7F9CCE02B00A77DC995C54C3831C18AE21DAC04537B7E998805FC338D53F7F&sign=9B9A0AD9295BDC084B6FB418523DEFA39D37C370 (Caused by NewConnectionError('<urllib3.connection.HTTPSConnection object at 0x7f6cf4288650>: Failed to establish a new connection: [Errno 101] Network is unreachable'))
### 执行结果
- **登录状态**: 登录失败
- **签到结果**: 

## 账户2
登录过程出错: HTTPSConnectionPool(host='open.e.189.cn', port=443): Max retries exceeded with url: /api/logbox/oauth2/autoLogin.do?appId=cloud&version=v1.1&clientType=20010&format=redirect&paras=999D5F6268A7BF91BA3311D29D98D15CDF1BDAF74CB6467C5FC829644FD817DFDB885020A8CC97F2391D74F7595E80E8F7CC6F7F58662F1D5ED3E98FD59F0DD700B8795F698FDC7A6BFC6F699DCA8490ABB4151C4F9DA24F2B77538774FCBCF97B5EEEDE8A188C601DF8DC7412A416C7BCA6B9EE019A44C548902E7CED22013CFF867737B1899A7A7F1723409CAE45DD81CB36DB2B2033F18E94909074FAB0A33FF6092ACD537808A19E70AAA0342342E316A78F695EADEAB3BD84789D2F2C6F62B5B57330EC621E1498A7595A9AC243480AB4A56A36081C1241CEF8E5276EE0822E56D9229CBAB2F18B9C129237F311B43F6A77617A2D52C9F50C77E919880B4DC01C4F7126EC60194580ED5EC3E1D427B6521909D084CFBD01518B0543073DAB89315F59E74846588666F37B98FD40379864E9427AD0560BA977CF170F4911A97129E08C0CF285F14D0701D4BCB4E318E9AD9CAA9C0BAA8D3E3888918B083E1D940A6DB9022BDEEA892B4214FC0E6D013C67EAA264197A76A9940D3076A2DD061B68FA5ED0B59D42A5D58DC0C089092DF39DA8C19C9C585F23802E6DCCE1083169B3BC8AC135128589699D9AAFD3E0E96F43A02BD967551FDBA16B1CBE4B2242B6F1AF9E1EA01523F81EADEAAE0124FF4183DF1B0B1CBFB0A99427863F4D55B7AD9796C1A37D8D46293A0A669C3F3D0C24E41FBFB206AF0724F596AEC85C92A47343E8056AF7598E17BD8EFA0E031CEDE7D7930DC73FD1&sign=F6EDA168CAEC85C9DEFA3B3851189AD99F05BC29 (Caused by NewConnectionError('<urllib3.connection.HTTPSConnection object at 0x7f6cf428bdd0>: Failed to establish a new connection: [Errno 101] Network is unreachable'))
### 执行结果
- **登录状态**: 登录失败
- **签到结果**: 

---
## 执行统计
- **结束时间**: 2025-10-21 21:59:24
- **运行时长**: 549.65 秒

✅ **所有账户处理完成！**
