# 天翼云盘签到记录

[![签到状态](https://github.com/chanho0/189pan/actions/workflows/main.yml/badge.svg)](https://github.com/chanho0/189pan/actions/workflows/main.yml) [![项目主页](https://img.shields.io/badge/GitHub-项目主页-blue?logo=github)](https://github.com/chanho0/189pan)

**最后更新:** 2025-10-19 11:03:18 CST

## 快速导航

- 🔄 [查看Action运行记录](https://github.com/chanho0/189pan/actions)
- 📋 [查看最新运行](https://github.com/chanho0/189pan/actions/runs/18624511504)
- 🏠 [返回项目主页](https://github.com/chanho0/189pan)
- ⚙️ [手动触发签到](https://github.com/chanho0/189pan/actions/workflows/main.yml)

## 签到详情

# 天翼云盘自动签到抽奖程序

## 执行概览
- **启动时间**: 2025-10-19 11:03:18
- **账户数量**: 2 个

## 账户1
登录过程出错: HTTPSConnectionPool(host='open.e.189.cn', port=443): Max retries exceeded with url: /api/logbox/oauth2/autoLogin.do?appId=cloud&version=v1.1&clientType=20010&format=redirect&paras=58E10B0E2A48709AD036DF6566594438F713A21565393BFDC4628E68E6A2BDE5870E83B6F355D460ABE069752C47C473F94767E1244A0EB604462B79F874FBCAD67BF330B3FB9BE8F7593985A6C7E664F457D06BF50E3B4B6DD089F839B79820CFBBFC3F99FCAB74AFD7688BA64129854BE37946614EE15D27B5D8F9D46A3CE273663E10CEEDC372DBFB23648F408B9B45D0AAE3F6A77271BD64FB7A9CC05780E9F133B98794BD331E9FFCE498C195EE973D3B8ED489386BC058088BB1F8CD6D349E9FD2C28E0FFB4876075F10CECB1027C1B617147250471FEBF5A0F9B7F285C6FA7808AE6D7EAB338DCE417674CA0D1FB5F0E9794090A02D192943230DD558F1D5DF50F280EE358735B8BF17C0EE541251F14C3095DF4E5D6AE07DABE247923DD13F418970FDCD0685874F90CDA2E09F8C87C4757AF68DB2DBF322B0E8B9325AED66AB4E0A4839DA5B2CF43E818699FA6D0F3224D441D76CAE89608B37AB0755EF22EB3ECB64E576E46FE6EAA4D23A47D250C7D73D6C7D1F47FBA1222894CB4BFCCBACB11F7C902F754EC08A1630250F22FFFDCB2BEFAE92AF136665E21817593C02B2619728E3706722BF4F48625BE1BE919267A9EC63AA6ED44E93D38720F98EC6CB007B4BD754893E1F794C62CA30A4F8C12A101D44042E708B798B039C184DC4947AF51485071F7D46F91C704BCCE6322BE03AF06AF2716034B4484AD8154F5147826F5512682FD441E23F24BD27293E5CD64121D4&sign=413E38A60873F8CA7383D9ACBB0B5525F8F36980 (Caused by NewConnectionError('<urllib3.connection.HTTPSConnection object at 0x7f05759b0b50>: Failed to establish a new connection: [Errno 101] Network is unreachable'))
### 执行结果
- **登录状态**: 登录失败
- **签到结果**: 

## 账户2
登录过程出错: HTTPSConnectionPool(host='open.e.189.cn', port=443): Max retries exceeded with url: /api/logbox/oauth2/autoLogin.do?appId=cloud&version=v1.1&clientType=20010&format=redirect&paras=F9540220362DC9C2F4FC796CE4BF6849D3D9AF744299A7D660CB31D5D41ABD7FCB47FEAFDD1E7497742917E779773BA9BA416A3193EB6568FB83D20DA58E7779A312B230D02FEF068BEF70942D851435E6F1DBCD95DDEF9A8C6309685F40671DCE0762F240B52DB2537D764A5EABFD3DEA4711D378860B0C59763BC26ECF74CD50F034C7BAA75FDFA89C835B502164249879CF30884D768DD068441FC678D4935C70E4C923B09F15E0CF2E2B2923CB6895FE160D7761321154160A0BDC8B75BFB660EFECC8AA05870B367C6275562503A40B92063571A78475FF96CF116056109697299D60C33C84AFCA559609B49BB82AB2C430ED502965AA7F6E40DFE92EFA2F3A035DF9FAC442F2EEEA7E7D7FA62017C5A96BBE62BF3F3D22512D07758F72E7A2279D7533A507FF4F8581EA1F594943C9C05D0DE650E09863426A6C9DC66589F754FBFB14CD6D631E25F2C5B27F91693ADAD1464303E4FB86B7AE10D5116F4B687478A05842CCFFE549E10805783631F5EA2874634472652B0FDD9E7E4FA189E24CF7361030C0A9AB937A222C09FFA18807FFFC90EB5DE3F1946DDBAE67F3C7E0E906D8D610B12BD28A357B68FBD6D2EB30DEB38ED476EE0FD1821D794993B99D2A8E23B4093ED765C07287FB8C6A4CA0CECC612ACFCBF436902F250C225B8721160D808C5E4B3D2329936AC045EEE82A3CA07271375D195236F22023CCFD22C940391AFC1EE02C3F4E92BE0279A4E9D0F79564952152&sign=1809EB3DCDD000572ECFAA81749282D0B77E8AE6 (Caused by NewConnectionError('<urllib3.connection.HTTPSConnection object at 0x7f05759b42d0>: Failed to establish a new connection: [Errno 101] Network is unreachable'))
### 执行结果
- **登录状态**: 登录失败
- **签到结果**: 

---
## 执行统计
- **结束时间**: 2025-10-19 11:12:24
- **运行时长**: 545.79 秒

✅ **所有账户处理完成！**
